<?xml version="1.0" encoding="utf-8"?>
<robot
  name="ROBOv2">
  <link
    name="base_link">
    <inertial>
      <origin
        xyz="0.000123937909243916 8.4765149139705E-07 0.0373948118449706"
        rpy="0 0 0" />
      <mass
        value="0.129198992435756" />
      <inertia
        ixx="0"
        ixy="0"
        ixz="0"
        iyy="0"
        iyz="0"
        izz="0" />
    </inertial>
    <visual>
      <origin
        xyz="0 0 0"
        rpy="0 0 0" />
      <geometry>
        <mesh
          filename="file://$(find ROBOv2)/meshes/base_link.STL" />
      </geometry>
      <material
        name="">
        <color
          rgba="0.627450980392157 0.627450980392157 0.627450980392157 1" />
      </material>
    </visual>
    <collision>
      <origin
        xyz="0 0 1"
        rpy="0 0 0" />
      <geometry>
        <cylinder
          radius="0.01"
          length="0.01" />
        <!-- <mesh
          filename="package://ROBOv2/meshes/base_link.STL" /> -->
      </geometry>
    </collision>
  </link>
  <link
    name="link1">
    <inertial>
      <origin
        xyz="1.43861340415614E-05 -0.00350542798523779 0.0168361695340248"
        rpy="0 0 0" />
      <mass
        value="0.135124042145669" />
      <inertia
        ixx="4.14837520709199E-05"
        ixy="-7.09562020474561E-10"
        ixz="5.34427272937233E-09"
        iyy="6.0260311153484E-05"
        iyz="-2.53028163395366E-07"
        izz="5.79394572859317E-05" />
    </inertial>
    <visual>
      <origin
        xyz="0 0 0"
        rpy="0 0 0" />
      <geometry>
        <mesh
          filename="file://$(find ROBOv2)/meshes/link1.STL" />
      </geometry>
      <material
        name="">
        <color
          rgba="0.627450980392157 0.627450980392157 0.627450980392157 1" />
      </material>
    </visual>
    <collision>
      <origin
        xyz="0 0 0"
        rpy="0 0 0" />
      <geometry>
        <cylinder
          radius="0.01"
          length="0.01" />
        <!-- <mesh
          filename="package://ROBOv2/meshes/link1.STL" /> -->
      </geometry>
    </collision>
  </link>
  <joint
    name="joint1"
    type="revolute">
    <origin
      xyz="0 0 0.0750000000000569"
      rpy="0 0 0" />
    <parent
      link="base_link" />
    <child
      link="link1" />
    <axis
      xyz="0 0 1" />
    <limit
      lower="-1.57"
      upper="1.57"
      effort="0"
      velocity="0" />
  </joint>
  <link
    name="link2">
    <inertial>
      <origin
        xyz="1.24161190220815E-05 -0.0501965424910991 -0.000609565825088086"
        rpy="0 0 0" />
      <mass
        value="0.155568086368024" />
      <inertia
        ixx="6.31144933853733E-05"
        ixy="-3.80613250733799E-11"
        ixz="-3.42419632538152E-10"
        iyy="3.99778418420942E-05"
        iyz="-3.12314684955805E-06"
        izz="8.08376649580164E-05" />
    </inertial>
    <visual>
      <origin
        xyz="0 0 0"
        rpy="0 0 0" />
      <geometry>
        <mesh
          filename="file://$(find ROBOv2)/meshes/link2.STL" />
      </geometry>
      <material
        name="">
        <color
          rgba="0.627450980392157 0.627450980392157 0.627450980392157 1" />
      </material>
    </visual>
    <collision>
      <origin
        xyz="0 0 0"
        rpy="0 0 0" />
      <geometry>
        <cylinder
          radius="0.01"
          length="0.01" />
        <!-- <mesh
          filename="package://ROBOv2/meshes/link2.STL" /> -->
      </geometry>
    </collision>
  </link>
  <joint
    name="joint2"
    type="revolute">
    <origin
      xyz="0 0 0.0275499999999431"
      rpy="-1.5707963267949 0 0" />
    <parent
      link="link1" />
    <child
      link="link2" />
    <axis
      xyz="0 0 -1" />
    <limit
      lower="-1.57"
      upper="1.57"
      effort="0"
      velocity="0" />
  </joint>
  <link
    name="link3">
    <inertial>
      <origin
        xyz="-0.0134759326284379 -0.0397279385467914 -0.00615339651949477"
        rpy="0 0 0" />
      <mass
        value="0.0706931108436309" />
      <inertia
        ixx="2.0957855975173E-05"
        ixy="-3.18342751503296E-06"
        ixz="1.11712400797395E-06"
        iyy="1.3047718793099E-05"
        iyz="4.38717094558408E-06"
        izz="2.03918242916651E-05" />
    </inertial>
    <visual>
      <origin
        xyz="0 0 0"
        rpy="0 0 0" />
      <geometry>
        <mesh
          filename="file://$(find ROBOv2)/meshes/link3.STL" />
      </geometry>
      <material
        name="">
        <color
          rgba="0.627450980392157 0.627450980392157 0.627450980392157 1" />
      </material>
    </visual>
    <collision>
      <origin
        xyz="0 0 0"
        rpy="0 0 0" />
      <geometry>
        <cylinder
          radius="0.01"
          length="0.01" />
        <!-- <mesh
          filename="package://ROBOv2/meshes/link3.STL" /> -->
      </geometry>
    </collision>
  </link>
  <joint
    name="joint3"
    type="revolute">
    <origin
      xyz="0 -0.091 0"
      rpy="0 0 0" />
    <parent
      link="link2" />
    <child
      link="link3" />
    <axis
      xyz="0 0 -1" />
    <limit
      lower="-1.57"
      upper="1.57"
      effort="0"
      velocity="0" />
  </joint>
  <link
    name="link4">
    <inertial>
      <origin
        xyz="1.43754558257214E-09 -0.000773219571640073 0.0377594897118048"
        rpy="0 0 0" />
      <mass
        value="0.0595055377002401" />
      <inertia
        ixx="2.3777353621544E-05"
        ixy="-4.49566704539174E-13"
        ixz="4.06262004603906E-12"
        iyy="2.42761648797602E-05"
        iyz="1.42802618650093E-06"
        izz="8.61432457030409E-06" />
    </inertial>
    <visual>
      <origin
        xyz="0 0 0"
        rpy="0 0 0" />
      <geometry>
        <mesh
          filename="file://$(find ROBOv2)/meshes/link4.STL" />
      </geometry>
      <material
        name="">
        <color
          rgba="0.627450980392157 0.627450980392157 0.627450980392157 1" />
      </material>
    </visual>
    <collision>
      <origin
        xyz="0 0 0"
        rpy="0 0 0" />
      <geometry>
        <cylinder
          radius="0.01"
          length="0.01" />
        <!-- <mesh
          filename="package://ROBOv2/meshes/link4.STL" /> -->
      </geometry>
    </collision>
  </link>
  <joint
    name="joint4"
    type="revolute">
    <origin
      xyz="0.021 -0.049000000000057 0"
      rpy="-1.5707963267949 0 -1.5707963267949" />
    <parent
      link="link3" />
    <child
      link="link4" />
    <axis
      xyz="0 0 -1" />
    <limit
      lower="-1.57"
      upper="1.57"
      effort="0"
      velocity="0" />
  </joint>
  <link
    name="link5">
    <inertial>
      <origin
        xyz="0.0266710461694476 -0.000127640614283359 -0.00359575669754987"
        rpy="0 0 0" />
      <mass
        value="0.0152811495589073" />
      <inertia
        ixx="9.52286289917837E-07"
        ixy="5.37530916338645E-10"
        ixz="-1.31831135365834E-07"
        iyy="2.51952311871716E-06"
        iyz="-9.01737283475658E-13"
        izz="2.65851744966292E-06" />
    </inertial>
    <visual>
      <origin
        xyz="0 0 0"
        rpy="0 0 0" />
      <geometry>
        <mesh
          filename="file://$(find ROBOv2)/meshes/link5.STL" />
      </geometry>
      <material
        name="">
        <color
          rgba="0.96078431372549 0.96078431372549 0.964705882352941 1" />
      </material>
    </visual>
    <collision>
      <origin
        xyz="0 0 0"
        rpy="0 0 0" />
      <geometry>
        <cylinder
          radius="0.01"
          length="0.01" />
        <!-- <mesh
          filename="package://ROBOv2/meshes/link5.STL" /> -->
      </geometry>
    </collision>
  </link>
  <joint
    name="joint5"
    type="revolute">
    <origin
      xyz="0 0 0.0927"
      rpy="1.5707963267949 -1.5707963267949 0" />
    <parent
      link="link4" />
    <child
      link="link5" />
    <axis
      xyz="0 0 1" />
    <limit
      lower="-1.57"
      upper="1.57"
      effort="0"
      velocity="0" />
  </joint>
  <link
    name="link6">
    <inertial>
      <origin
        xyz="-0.000193405535626606 -0.000435778410579226 0.0334396807455861"
        rpy="0 0 0" />
      <mass
        value="0.0176750948998686" />
      <inertia
        ixx="3.7805850683409E-06"
        ixy="-2.22787441588436E-10"
        ixz="-6.79858868750768E-08"
        iyy="2.51877469055783E-06"
        iyz="4.21287523555918E-08"
        izz="1.9909376137199E-06" />
    </inertial>
    <visual>
      <origin
        xyz="0 0 0"
        rpy="0 0 0" />
      <geometry>
        <box
          size="0.001 0.001 0.001" />
        <!-- <mesh
          filename="file://$(find ROBOv2)/meshes/link6.STL" /> -->
      </geometry>
      <material
        name="">
        <color
          rgba="0.627450980392157 0.627450980392157 0.627450980392157 1" />
      </material>
    </visual>
    <collision>
      <origin
        xyz="0 0 0"
        rpy="0 0 0" />
      <geometry>
        <cylinder
          radius="0.01"
          length="0.01" />
        <!-- <mesh
          filename="package://ROBOv2/meshes/link6.STL" /> -->
      </geometry>
    </collision>
  </link>
  <joint
    name="joint6"
    type="revolute">
    <origin
      xyz="0.04575 0 0"
      rpy="-1.5708 0 -1.5708" />
    <parent
      link="link5" />
    <child
      link="link6" />
    <axis
      xyz="0 0 1" />
    <limit
      lower="-1.57"
      upper="1.57"
      effort="0"
      velocity="0" />
  </joint>
    <!--camera_link-->
  <link name = "camera_link">
    <collision>
      <origin
        xyz="0 0 0"
        rpy="0 0 0" />
      <!--<geometry>
        <box size="0.001 0.001 0.001"/>
      </geometry>-->
    </collision>
    <visual>
      <geometry>
        <sphere radius="0.01"/>
      </geometry>
      <material name="red">
        <color rgba="1 0 0 1"/>
      </material>
    </visual>
    <inertia>
      <origin xyz="0 0 0" rpy="0 0 0"/>
      <mass value="0.01"/>
      <inertia ixx="0.0001" ixy="0.0" ixz="0.0" iyy="0.0001" iyz="0.0" izz="0.0001"/>
    </inertia>
  </link>
  <joint name="camera_joint" type="fixed">
    <origin xyz="0 0 0" rpy="3.1416 -1.5708 0"/>
    <parent link="link6"/>
    <child link="camera_link"/>
  </joint>
</robot>
