<?xml version="1.0" encoding="utf-8"?>
<robot
  name="robo6">
  <link
    name="base_link">
    <inertial>
      <origin
        xyz="1.878E-06 0.028912 -1.3038E-05"
        rpy="0 0 0" />
      <mass
        value="0.12045" />
      <inertia
        ixx="0"
        ixy="0"
        ixz="0"
        iyy="0"
        iyz="0"
        izz="0" />
    </inertial>
    <visual>
      <origin
        xyz="0 0 0"
        rpy="0 0 0" />
      <geometry>
        <mesh
          filename="file://$(find robo6)/meshes/base_link.STL" />
      </geometry>
      <material
        name="">
        <color
          rgba="0.96078 0.96078 0.96471 1" />
      </material>
    </visual>
    <collision>
      <origin
        xyz="0 0 1"
        rpy="0 0 0" />
      <geometry>
        <cylinder
          radius="0.01"
          length="0.01" />
        <!-- <mesh
          filename="/home/duallife/projects/urdf/robo6/meshes/base_link.STL" /> -->
      </geometry>
    </collision>
  </link>
  <link
    name="Link1">
    <inertial>
      <origin
        xyz="-4.92527363388455E-08 0.0349442574396109 0.000307533695580413"
        rpy="0 0 0" />
      <mass
        value="0.0659118172201022" />
      <inertia
        ixx="2.36472823445046E-05"
        ixy="-2.80763181176182E-11"
        ixz="-8.9871698594769E-12"
        iyy="3.18142849528654E-05"
        iyz="-1.84244071707729E-09"
        izz="2.94979037366588E-05" />
    </inertial>
    <visual>
      <origin
        xyz="0 0 0"
        rpy="0 0 0" />
      <geometry>
        <mesh
          filename="file://$(find robo6)/meshes/Link1.STL" />
      </geometry>
      <material
        name="">
        <color
          rgba="0.96078431372549 0.96078431372549 0.964705882352941 1" />
      </material>
    </visual>
    <collision>
      <origin
        xyz="0 0 0"
        rpy="0 0 0" />
      <geometry>
        <mesh
          filename="file://$(find robo6)/meshes/Link1.STL" />
      </geometry>
    </collision>
  </link>
  <joint
    name="Joint1"
    type="revolute">
    <origin
      xyz="0 0 0.0415"
      rpy="1.5707 0 0" />
    <parent
      link="base_link" />
    <child
      link="Link1" />
    <axis
      xyz="0 1 0" />
    <limit
      lower="-3.14"
      upper="3.14"
      effort="0"
      velocity="0" />
  </joint>
  <link
    name="Link2">
    <inertial>
      <origin
        xyz="5.24382262826091E-06 0.0536410224280989 -0.00443745142661563"
        rpy="0 0 0" />
      <mass
        value="0.15354999870256" />
      <inertia
        ixx="6.48684049795887E-05"
        ixy="-3.90286701622052E-11"
        ixz="-2.55081782957912E-09"
        iyy="4.61126385560208E-05"
        iyz="1.05957379714566E-06"
        izz="7.71458832673368E-05" />
    </inertial>
    <visual>
      <origin
        xyz="0 0 0"
        rpy="0 0 0" />
      <geometry>
        <mesh
          filename="file://$(find robo6)/meshes/Link2.STL" />
      </geometry>
      <material
        name="">
        <color
          rgba="0.627450980392157 0.627450980392157 0.627450980392157 1" />
      </material>
    </visual>
    <collision>
      <origin
        xyz="0 0 0"
        rpy="0 0 0" />
      <geometry>
        <mesh
          filename="file://$(find robo6)/meshes/Link2.STL" />
      </geometry>
    </collision>
  </link>
  <joint
    name="Joint2"
    type="revolute">
    <origin
      xyz="0 0.0535 0"
      rpy="0 0 0" />
    <parent
      link="Link1" />
    <child
      link="Link2" />
    <axis
      xyz="0 0 1" />
    <limit
      lower="-1"
      upper="1.57"
      effort="0"
      velocity="0" />
  </joint>
  <link
    name="Link3">
    <inertial>
      <origin
        xyz="0.0120475717228843 0.035035947202792 -0.00518320114030269"
        rpy="0 0 0" />
      <mass
        value="0.0676002455536992" />
      <inertia
        ixx="1.47656579114417E-05"
        ixy="-2.44665581059836E-06"
        ixz="6.15842251805329E-09"
        iyy="1.00493633448293E-05"
        iyz="-5.45934098629043E-07"
        izz="1.60840921021648E-05" />
    </inertial>
    <visual>
      <origin
        xyz="0 0 0"
        rpy="0 0 0" />
      <geometry>
        <mesh
          filename="file://$(find robo6)/meshes/Link3.STL" />
      </geometry>
      <material
        name="">
        <color
          rgba="0.627450980392157 0.627450980392157 0.627450980392157 1" />
      </material>
    </visual>
    <collision>
      <origin
        xyz="0 0 0"
        rpy="0 0 0" />
      <geometry>
        <mesh
          filename="file://$(find robo6)/meshes/Link3.STL" />
      </geometry>
    </collision>
  </link>
  <joint
    name="Joint3"
    type="revolute">
    <origin
      xyz="0 0.099 0"
      rpy="0 0 0" />
    <parent
      link="Link2" />
    <child
      link="Link3" />
    <axis
      xyz="0 0 1" />
    <limit
      lower="-1"
      upper="1"
      effort="0"
      velocity="0" />
  </joint>
  <link
    name="Link4">
    <inertial>
      <origin
        xyz="-0.0512830210113846 -3.4037477542187E-05 0.000741205706793905"
        rpy="0 0 0" />
      <mass
        value="0.0504466173853801" />
      <inertia
        ixx="7.08603575326675E-06"
        ixy="-2.26434036239613E-11"
        ixz="1.54581220155489E-06"
        iyy="2.21919182212061E-05"
        iyz="-2.04152826538135E-08"
        izz="2.23021426371424E-05" />
    </inertial>
    <visual>
      <origin
        xyz="0 0 0"
        rpy="0 0 0" />
      <geometry>
        <mesh
          filename="file://$(find robo6)/meshes/Link4.STL" />
      </geometry>
      <material
        name="">
        <color
          rgba="0.627450980392157 0.627450980392157 0.627450980392157 1" />
      </material>
    </visual>
    <collision>
      <origin
        xyz="0 0 0"
        rpy="0 0 0" />
      <geometry>
        <mesh
          filename="file://$(find robo6)/meshes/Link4.STL" />
      </geometry>
    </collision>
  </link>
  <joint
    name="Joint4"
    type="revolute">
    <origin
      xyz="-0.014187 0.041909 0"
      rpy="0 0 0" />
    <parent
      link="Link3" />
    <child
      link="Link4" />
    <axis
      xyz="1 0 0" />
    <limit
      lower="-3.14"
      upper="3.14"
      effort="0"
      velocity="0" />
  </joint>
  <link
    name="Link5">
    <inertial>
      <origin
        xyz="-0.028276116522767 -0.000114515854134301 -0.00387887665408256"
        rpy="0 0 0" />
      <mass
        value="0.017028601675043" />
      <inertia
        ixx="1.11109669358206E-06"
        ixy="-5.36640838203033E-10"
        ixz="2.17603339184217E-07"
        iyy="3.63221196171804E-06"
        iyz="-3.22059682421302E-13"
        izz="3.7981188308525E-06" />
    </inertial>
    <visual>
      <origin
        xyz="0 0 0"
        rpy="0 0 0" />
      <geometry>
        <mesh
          filename="file://$(find robo6)/meshes/Link5.STL" />
      </geometry>
      <material
        name="">
        <color
          rgba="0.96078431372549 0.96078431372549 0.964705882352941 1" />
      </material>
    </visual>
    <collision>
      <origin
        xyz="0 0 0"
        rpy="0 0 0" />
      <geometry>
        <mesh
          filename="file://$(find robo6)/meshes/Link5.STL" />
      </geometry>
    </collision>
  </link>
  <joint
    name="Joint5"
    type="revolute">
    <origin
      xyz="-0.10397 0 0"
      rpy="0 0 0" />
    <parent
      link="Link4" />
    <child
      link="Link5" />
    <axis
      xyz="0 0 1" />
    <limit
      lower="-2.6"
      upper="2.6"
      effort="0"
      velocity="0" />
  </joint>
  <link
    name="Link6">
    <inertial>
      <origin
        xyz="-0.00527028329076445 3.45215899660856E-06 -5.55111512312578E-17"
        rpy="0 0 0" />
      <mass
        value="0.000951131899037555" />
      <inertia
        ixx="4.15899516019936E-08"
        ixy="2.14226853954163E-24"
        ixz="7.47047490711953E-24"
        iyy="1.0274043664262E-08"
        iyz="-8.27180612553028E-25"
        izz="3.52789575170549E-08" />
    </inertial>
    <visual>
      <origin
        xyz="0 0 0"
        rpy="0 0 0" />
      <geometry>
        <mesh
          filename="file://$(find robo6)/meshes/Link6.STL" />
      </geometry>
      <material
        name="">
        <color
          rgba="0.627450980392157 0.627450980392157 0.627450980392157 1" />
      </material>
    </visual>
    <collision>
      <origin
        xyz="0 0 0"
        rpy="0 0 0" />
      <geometry>
        <mesh
          filename="file://$(find robo6)/meshes/Link6.STL" />
      </geometry>
    </collision>
  </link>
  <joint
    name="Joint6"
    type="revolute">
    <origin
      xyz="-0.05773 0 0"
      rpy="0 0 0" />
    <parent
      link="Link5" />
    <child
      link="Link6" />
    <axis
      xyz="1 0 0" />
    <limit
      lower="-3.14"
      upper="3.14"
      effort="0"
      velocity="0" />
  </joint>
</robot>
